<?xml version="1.0" ?>
<!-- =================================================================================== -->
<!-- |    This document was autogenerated by xacro from /opt/ros/kinetic/share/moveit_resources/panda_description/urdf/panda.urdf | -->
<!-- |    EDITING THIS FILE BY HAND IS NOT RECOMMENDED                                 | -->
<!-- =================================================================================== -->
<robot name="RobotArm" xmlns:xacro="http://www.ros.org/wiki/xacro">
    <link name="base_link">
        <visual>
            <geometry>
                <mesh filename="package://moveit_resources_panda_description/meshes/collision/base_link.stl" scale="0.001 0.001 0.001"/>
            </geometry>
        </visual>
        <collision>
            <geometry>
                <mesh filename="package://moveit_resources_panda_description/meshes/collision/base_link.stl" scale="0.001 0.001 0.001"/>
            </geometry>
        </collision>
    </link>
    <link name="Componente4_1">
        <visual>
            <geometry>
                <mesh filename="package://moveit_resources_panda_description/meshes/collision/Componente4_1.stl" scale="0.001 0.001 0.001"/>
            </geometry>
        </visual>
        <collision>
            <geometry>
                <mesh filename="package://moveit_resources_panda_description/meshes/collision/Componente4_1.stl" scale="0.001 0.001 0.001"/>
            </geometry>
        </collision>
    </link>
    <joint name="limb1_to_base_link" type="revolute">
        <safety_controller k_position="100.0" k_velocity="40.0" soft_lower_limit="-2.8973" soft_upper_limit="2.8973" />
        <origin rpy="0 0 0" xyz="0.0 0.0 0.15" />
        <parent link="base_link" />
        <child link="Componente4_1" />
        <axis xyz="0.0 0.0 1.0" />
        <limit effort="100" lower="-2.9671" upper="2.9671" velocity="100" />
    </joint>
    <link name="Componente5_1">
        <visual>
            <geometry>
                <mesh filename="package://moveit_resources_panda_description/meshes/collision/Componente5_1.stl" scale="0.001 0.001 0.001"/>
            </geometry>
        </visual>
        <collision>
            <geometry>
                <mesh filename="package://moveit_resources_panda_description/meshes/collision/Componente5_1.stl" scale="0.001 0.001 0.001"/>
            </geometry>
        </collision>
    </link>
    <joint name="limb2_to_limb1" type="revolute">
        <safety_controller k_position="100.0" k_velocity="40.0" soft_lower_limit="-1.55" soft_upper_limit="1.55" />
        <origin rpy="0 0 0" xyz="0.0 -0.1 0.1" />
        <parent link="Componente4_1" />
        <child link="Componente5_1" />
        <axis xyz="0.0 -1.0 0.0" />
        <limit effort="100" lower="-1.570796" upper="1.570796" velocity="100" />
    </joint>
    <link name="Componente6_1">
        <visual>
            <geometry>
                <mesh filename="package://moveit_resources_panda_description/meshes/collision/Componente6_1.stl" scale="0.001 0.001 0.001"/>
            </geometry>
        </visual>
        <collision>
            <geometry>
                <mesh filename="package://moveit_resources_panda_description/meshes/collision/Componente6_1.stl" scale="0.001 0.001 0.001"/>
            </geometry>
        </collision>
    </link>
    <joint name="limb3_to_limb2" type="revolute">
        <safety_controller k_position="100.0" k_velocity="40.0" soft_lower_limit="-2.8973" soft_upper_limit="2.8973" />
        <origin rpy="0 0 0" xyz="0.0 -0.1 0.3" />
        <parent link="Componente5_1" />
        <child link="Componente6_1" />
        <axis xyz="0.0 0.0 1.0" />
        <limit effort="100" lower="-2.9671" upper="2.9671" velocity="100" />
    </joint>
    <link name="Componente7_1">
        <visual>
            <geometry>
                <mesh filename="package://moveit_resources_panda_description/meshes/collision/Componente7_1.stl" scale="0.001 0.001 0.001"/>
            </geometry>
        </visual>
        <collision>
            <geometry>
                <mesh filename="package://moveit_resources_panda_description/meshes/collision/Componente7_1.stl" scale="0.001 0.001 0.001"/>
            </geometry>
        </collision>
    </link>
    <joint name="limb4_to_limb3" type="revolute">
        <safety_controller k_position="100.0" k_velocity="40.0" soft_lower_limit="-2.77" soft_upper_limit="2.77" />
        <origin rpy="0 0 0" xyz="0.0 0.1 0.1" />
        <parent link="Componente6_1" />
        <child link="Componente7_1" />
        <axis xyz="0.0 1.0 0.0" />
        <limit effort="100" lower="-2.792527" upper="2.792527" velocity="100" />
    </joint>
    <link name="Componente8_1">
        <visual>
            <geometry>
                <mesh filename="package://moveit_resources_panda_description/meshes/visual/link5.dae" scale="0.001 0.001 0.001"/>
            </geometry>
        </visual>
        <collision>
            <geometry>
                <mesh filename="package://moveit_resources_panda_description/meshes/collision/Componente8_1.stl" scale="0.001 0.001 0.001"/>
            </geometry>
        </collision>
    </link>
    <joint name="limb5_to_limb4" type="revolute">
        <safety_controller k_position="100.0" k_velocity="40.0" soft_lower_limit="-2.8973" soft_upper_limit="2.8973" />
        <origin rpy="0 0 0" xyz="0.0 0.1 0.4" />
        <parent link="Componente7_1" />
        <child link="Componente8_1" />
        <axis xyz="0.0 0.0 1.0" />
        <limit effort="100" lower="-2.9671" upper="2.9671" velocity="100" />
    </joint>
</robot>
