<?xml version="1.0" ?>
<robot name="RobotArm" xmlns:xacro="http://www.ros.org/wiki/xacro">

  <link name="base_link">
    <visual>
      <origin xyz="0 0 0" rpy="0 0 0"/>
      <geometry>
        <mesh filename="package://moveit_resources_panda_description/meshes/collision/base_link.stl" scale="0.001 0.001 0.001"/>
      </geometry>
    </visual>
    <collision>
      <origin xyz="0 0 0" rpy="0 0 0"/>
      <geometry>
        <mesh filename="package://moveit_resources_panda_description/meshes/collision/base_link.stl" scale="0.001 0.001 0.001"/>
      </geometry>
    </collision>
  </link>

  <link name="Componente4_1">
    <visual>
      <origin xyz="0.0 0.0 -0.15" rpy="0 0 0"/>
      <geometry>
        <mesh filename="package://moveit_resources_panda_description/meshes/collision/Componente4_1.stl" scale="0.001 0.001 0.001"/>
      </geometry>
    </visual>
    <collision>
      <origin xyz="0.0 0.0 -0.15" rpy="0 0 0"/>
      <geometry>
        <mesh filename="package://moveit_resources_panda_description/meshes/collision/Componente4_1.stl" scale="0.001 0.001 0.001"/>
      </geometry>
    </collision>
  </link>

  <link name="Componente5_1">
    <visual>
      <origin xyz="0.0 0.1 -0.25" rpy="0 0 0"/>
      <geometry>
        <mesh filename="package://moveit_resources_panda_description/meshes/collision/Componente5_1.stl" scale="0.001 0.001 0.001"/>
      </geometry>
    </visual>
    <collision>
      <origin xyz="0.0 0.1 -0.25" rpy="0 0 0"/>
      <geometry>
        <mesh filename="package://moveit_resources_panda_description/meshes/collision/Componente5_1.stl" scale="0.001 0.001 0.001"/>
      </geometry>
    </collision>
  </link>

  <link name="Componente6_1">
    <visual>
      <origin xyz="0.0 0.2 -0.55" rpy="0 0 0"/>
      <geometry>
        <mesh filename="package://moveit_resources_panda_description/meshes/collision/Componente6_1.stl" scale="0.001 0.001 0.001"/>
      </geometry>
    </visual>
    <collision>
      <origin xyz="0.0 0.2 -0.55" rpy="0 0 0"/>
      <geometry>
        <mesh filename="package://moveit_resources_panda_description/meshes/collision/Componente6_1.stl" scale="0.001 0.001 0.001"/>
      </geometry>
    </collision>
  </link>

  <link name="Componente7_1">
    <visual>
      <origin xyz="0.0 0.1 -0.65" rpy="0 0 0"/>
      <geometry>
        <mesh filename="package://moveit_resources_panda_description/meshes/collision/Componente7_1.stl" scale="0.001 0.001 0.001"/>
      </geometry>
    </visual>
    <collision>
      <origin xyz="0.0 0.1 -0.65" rpy="0 0 0"/>
      <geometry>
        <mesh filename="package://moveit_resources_panda_description/meshes/collision/Componente7_1.stl" scale="0.001 0.001 0.001"/>
      </geometry>
    </collision>
  </link>

  <link name="Componente8_1">
    <visual>
      <origin xyz="0.0 0.0 -1.05" rpy="0 0 0"/>
      <geometry>
        <mesh filename="package://moveit_resources_panda_description/meshes/collision/Componente8_1.stl" scale="0.001 0.001 0.001"/>
      </geometry>
    </visual>
    <collision>
      <origin xyz="0.0 0.0 -1.05" rpy="0 0 0"/>
      <geometry>
        <mesh filename="package://moveit_resources_panda_description/meshes/collision/Componente8_1.stl" scale="0.001 0.001 0.001"/>
      </geometry>
    </collision>
  </link>

  <joint name="limb1_to_base_link" type="continuous">
    <safety_controller k_position="100.0" k_velocity="40.0" /> <origin xyz="0.0 0.0 0.15" rpy="0 0 0"/>
    <parent link="base_link"/>
    <child link="Componente4_1"/>
    <axis xyz="0.0 0.0 1.0"/>
    <limit effort="100" velocity="100"/> </joint>

  <joint name="limb2_to_limb1" type="revolute">
    <safety_controller k_position="100.0" k_velocity="40.0" soft_lower_limit="-1.55" soft_upper_limit="1.55" /> <origin xyz="0.0 -0.1 0.1" rpy="0 0 0"/>
    <parent link="Componente4_1"/>
    <child link="Componente5_1"/>
    <axis xyz="0.0 -1.0 0.0"/>
    <limit effort="100" lower="-1.570796" upper="1.570796" velocity="100"/>
  </joint>

  <joint name="limb3_to_limb2" type="continuous">
    <safety_controller k_position="100.0" k_velocity="40.0" />
    <origin xyz="0.0 -0.1 0.3" rpy="0 0 0"/>
    <parent link="Componente5_1"/>
    <child link="Componente6_1"/>
    <axis xyz="0.0 0.0 1.0"/>
    <limit effort="100" velocity="100"/> </joint>

  <joint name="limb4_to_limb3" type="revolute">
    <safety_controller k_position="100.0" k_velocity="40.0" soft_lower_limit="-2.77" soft_upper_limit="2.77" />
    <origin xyz="0.0 0.1 0.1" rpy="0 0 0"/>
    <parent link="Componente6_1"/>
    <child link="Componente7_1"/>
    <axis xyz="0.0 1.0 0.0"/>
    <limit effort="100" lower="-2.792527" upper="2.792527" velocity="100"/>
  </joint>

  <joint name="limb5_to_limb4" type="continuous">
    <safety_controller k_position="100.0" k_velocity="40.0" />
    <origin xyz="0.0 0.1 0.4" rpy="0 0 0"/>
    <parent link="Componente7_1"/>
    <child link="Componente8_1"/>
    <axis xyz="0.0 0.0 1.0"/>
    <limit effort="100" velocity="100"/> </joint>

  </robot>
